<?xml version="1.0"?>
<robot xmlns:xacro="http://www.ros.org/wiki/xacro" name="urdf_tutorial">

    <!-- MACROS -->
    <xacro:include filename="macros.xacro"/>

    <!-- COLOR -->
    <material name="white">
        <color rgba="1 1 1 1" />
    </material>

    <material name="blue">
        <color rgba="0 0 1 1"/>
    </material>

    <material name="black">
        <color rgba="0 0 0 1"/>
    </material>

    <!-- BASE LINK -->
    <link name="base_footprint">
        <visual>
            <origin xyz="0 0 0"/>
        </visual>
    </link>

    <!-- BODY LINK -->
    <joint name="base_joint" type="fixed">
        <parent link="base_footprint"/>
        <child link="base_link"/>
        <origin xyz="0 0 0.525"/>
    </joint>

    <link name="base_link">
        <visual>
            <origin xyz="-0.345 0 0"/>
            <geometry>
                <box size="0.83 0.52 0.57"/>
            </geometry>
            <material name="white"/>
        </visual>
        <collision>
            <origin xyz="-0.345 0 0"/>
            <geometry>
                <box size="0.83 0.52 0.57"/>
            </geometry>
        </collision>
        <xacro:inertial_box mass="0.5" x="0.83" y="0.52" z="0.57">
            <origin xyz="-0.345 0 0" rpy="0 0 0"/>
        </xacro:inertial_box>
    </link>

    <!-- WHEEL ATTACHMENT -->
    <joint name="wheel_attachment_joint" type="fixed">
        <parent link="base_footprint"/>
        <child link="wheel_attachment"/>
        <origin xyz="0 0 0.127"/>
    </joint>

    <link name="wheel_attachment">
        <visual>
            <origin xyz="0 0 0"/>
            <geometry>
                <box size="0.1 0.59 0.1"/>
            </geometry>
            <material name="white"/>
        </visual>
        <collision>
            <origin xyz="0 0 0"/>
            <geometry>
                <box size="0.1 0.59 0.1"/>
            </geometry>
        </collision>
        <xacro:inertial_box mass="0.5" x="0.1" y="0.59" z="0.1">
            <origin xyz="0 0 0" rpy="0 0 0"/>
        </xacro:inertial_box>
    </link>

    <!-- WHEEL ATTACHMENT ADD -->
    <joint name="wheel_attachment_add_joint" type="fixed">
        <parent link="base_footprint"/>
        <child link="wheel_attachment_add"/>
        <origin xyz="0 0 0.1835"/>
    </joint>

    <link name="wheel_attachment_add">
        <visual>
            <origin xyz="0 0 0"/>
            <geometry>
                <box size="0.1 0.52 0.113"/>
            </geometry>
            <material name="white"/>
        </visual>
        <collision>
            <origin xyz="0 0 0"/>
            <geometry>
                <box size="0.1 0.52 0.113"/>
            </geometry>
        </collision>
        <xacro:inertial_box mass="0.5" x="0.1" y="0.52" z="0.113">
            <origin xyz="0 0 0" rpy="0 0 0"/>
        </xacro:inertial_box>
    </link>


    <!-- LEFT WHEEL LINK  continuous / fixed -->
    <joint name="left_wheel_joint" type="continuous">
        <parent link="base_footprint"/>
        <child link="left_wheel"/>
        <origin xyz="0 0.33 0.127" rpy="-${pi/2} 0 0" />
        <axis xyz="0 0 1"/>
    </joint>

    <link name="left_wheel">
        <visual>
            <geometry>
                <cylinder radius="0.127" length="0.06"/>
            </geometry>
            <material name="blue"/>
        </visual>
        <collision>
            <geometry>
                <cylinder radius="0.127" length="0.06"/>
            </geometry>
        </collision>
        <xacro:inertial_cylinder mass="0.1" length="0.06" radius="0.127">
            <origin xyz="0 0 0" rpy="0 0 0"/>
        </xacro:inertial_cylinder>
    </link>

    <!-- RIGHT WHEEL LINK  continuous / fixed -->
    <joint name="right_wheel_joint" type="continuous">
        <parent link="base_footprint"/>
        <child link="right_wheel"/>
        <origin xyz="0 -0.33 0.127" rpy="${pi/2} 0 0" />
        <axis xyz="0 0 -1"/>
    </joint>

    <link name="right_wheel">
        <visual>
            <geometry>
                <cylinder radius="0.127" length="0.06"/>
            </geometry>
            <material name="blue"/>
        </visual>
        <collision>
            <geometry>
                <cylinder radius="0.127" length="0.06"/>
            </geometry>
        </collision>
        <xacro:inertial_cylinder mass="0.1" length="0.06" radius="0.127">
            <origin xyz="0 0 0" rpy="0 0 0"/>
        </xacro:inertial_cylinder>
    </link>

    <!-- CASTER ATTACHMENT -->
    <joint name="caster_attachment_joint" type="fixed">
        <parent link="base_footprint"/>
        <child link="caster_attachment"/>
        <origin xyz="-0.56 0 0.16"/>
    </joint>

    <link name="caster_attachment">
        <visual>
            <origin xyz="0 0 0"/>
            <geometry>
                <box size="0.4 0.4 0.16"/>
            </geometry>
            <material name="white"/>
        </visual>
        <collision>
            <origin xyz="0 0 0"/>
            <geometry>
                <box size="0.4 0.4 0.16"/>
            </geometry>
        </collision>
        <xacro:inertial_box mass="0.5" x="0.4" y="0.4" z="0.16">
            <origin xyz="0 0 0" rpy="0 0 0"/>
        </xacro:inertial_box>
    </link>

    <!-- CASTER WHEEL LINK -->
    <joint name="caster_wheel_joint" type="fixed">
        <parent link="caster_attachment"/>
        <child link="caster_wheel"/>
        <origin xyz="0 0 -0.08"/>
    </joint>

    <link name="caster_wheel">
        <visual>
            <geometry>
                <sphere radius="0.08"/>
            </geometry>
            <material name="blue"/>
        </visual>
        <collision>
            <geometry>
                <sphere radius="0.08"/>
            </geometry>
        </collision>
        <xacro:inertial_sphere mass="0.1" radius="0.08">
            <origin xyz="0 0 0" rpy="0 0 0"/>
        </xacro:inertial_sphere>
    </link>

    <!-- BASE SCAN -->
    <joint name="scan_joint" type="fixed">
        <parent link="base_footprint"/>
        <child link="base_scan"/>
        <origin xyz="0 0 0"/>
    </joint>

    <link name="base_scan">
        <visual>
            <origin xyz="0 0 0.8525"/>
            <geometry>
                <box size="0.065 0.075 0.085"/>
            </geometry>
            <material name="black"/>
        </visual>

        <collision>
            <origin xyz="0 0 0.8525"/>
            <geometry>
                <box size="0.065 0.075 0.085"/>
            </geometry>
        </collision>
        <xacro:inertial_box mass="0.1" x="0.065" y="0.075" z="0.085">
            <origin xyz="0.05 0 0.0425" rpy="0 0 0"/>
        </xacro:inertial_box>
    </link>

    <!-- IMU SCAN -->
    <joint name="imu_joint" type="fixed">
        <parent link="base_footprint"/>
        <child link="imu_link"/>
        <origin xyz="0 0 0"/>
    </joint>

    <link name="imu_link"/>

</robot>
